Workbook

Sheet Start Here
A1: TAFAMIND PLANNER
A3: Niyyah · Yaqiin · Amal | A practical intention, belief, action & reflection system
B5: WELCOME
B6: A simple system for turning meaningful intentions into consistent daily practice.
B8: THE 3-PILLAR METHOD
B9: NIYYAH — define what you want and why it matters. YAQIIN — notice and strengthen your belief through daily reflection. AMAL — turn the goal into repeatable actions and track what you actually do.
B13: QUICK START
B14: 1. Open Goals (Niyyah) and add your goals. Mark ONE goal as Primary. 2. Open Actions Tracker and set Month starting to the first day of your month. Add up to 20 habits/actions. 3. Each day, enter 1 for done or 0 for missed. Leave future days blank. 4. Use Belief Tracker each day for a 1–10 belief score and one honest note. 5. Use Manifest Board for Ask, Gratitude and Receive entries. 6. Use Daily Journal for reflection, wins, lessons and tomorrow’s focus. 7. Return to Dashboard for your live snapshot.
B22: INPUT vs. CALCULATED CELLS
B23: Blue text / pale blue cells = you type here. Dark text / white cells = calculated or system-managed and are locked to protect formulas. Sheets are protected (no password) — only the editable cells above can be typed into.
B26: PRODUCT SETUP NOTES
B27: This is an undated digital template. Set your month once in Actions Tracker; linked daily sheets update automatically. Keep a master copy. For resale, distribute a clean duplicate with your own brand, license terms and support details added.

Sheet Dashboard
A1: TAFAMIND DASHBOARD
A3: Your goals, actions, belief and reflection — summarized in one place.
A5: PRIMARY GOAL
A6: =IFERROR(INDEX('Goals (Niyyah)'!B:B,MATCH("Yes",'Goals (Niyyah)'!H:H,0)),"Set one goal to Primary") -> Set one goal to Primary
A7: =IFERROR("Affirmation: "&INDEX('Goals (Niyyah)'!E:E,MATCH("Yes",'Goals (Niyyah)'!H:H,0)),"Add an affirmation to your Primary goal.") -> Add an affirmation to your Primary goal.
A8: =IFERROR("Target date: "&TEXT(INDEX('Goals (Niyyah)'!G:G,MATCH("Yes",'Goals (Niyyah)'!H:H,0)),"dd mmm yyyy")&" · Days left: "&MAX(0,INDEX('Goals (Niyyah)'!G:G,MATCH("Yes",'Goals (Niyyah)'!H:H,0))-TODAY()),"Set a target date to see your countdown.") -> Set a target date to see your countdown.
A9: =IFERROR("Action rate: "&TEXT(INDEX('Goals (Niyyah)'!K:K,MATCH("Yes",'Goals (Niyyah)'!H:H,0)),"0.0%")&" · Avg belief: "&INDEX('Goals (Niyyah)'!L:L,MATCH("Yes",'Goals (Niyyah)'!H:H,0))&" / 10","Add actions and belief entries to see progress.") -> Add actions and belief entries to see progress.
A11: SETUP CHECK
A12: =IF(COUNTIF('Goals (Niyyah)'!H6:H35,"Yes")=1,"✓ Ready — one Primary goal is selected.",IF(COUNTIF('Goals (Niyyah)'!H6:H35,"Yes")=0,"! Select one Primary goal on Goals (Niyyah).","! More than one Primary goal is selected — keep only one.")) -> ! Select one Primary goal on Goals (Niyyah).
A15: Action completion | D15: Average belief | G15: Current streak
A16: ='Actions Tracker'!AL27 -> - | D16: =IFERROR(ROUND(AVERAGE('Belief Tracker'!C6:C65),1),"-") -> - | G16: =IFERROR(LOOKUP(2,1/('Actions Tracker'!E29:AI29<>""),'Actions Tracker'!E29:AI29),0) -> 0
A19: Actions done | D19: Actions missed | G19: Journal days
A20: ='Actions Tracker'!AJ27 -> 0 | D20: ='Actions Tracker'!AK27 -> 0 | G20: =COUNTA('Daily Journal'!B6:B65) -> 0
A24: HABIT SNAPSHOT
A25: Habit | B25: Done | D25: Missed | E25: Rate
A26: =IF('Actions Tracker'!A6="","",'Actions Tracker'!A6) | B26: =IF('Actions Tracker'!A6="","",'Actions Tracker'!AJ6) | D26: =IF('Actions Tracker'!A6="","",'Actions Tracker'!AK6) | E26: =IF('Actions Tracker'!A6="","",'Actions Tracker'!AL6)
A27: =IF('Actions Tracker'!A7="","",'Actions Tracker'!A7) | B27: =IF('Actions Tracker'!A7="","",'Actions Tracker'!AJ7) | D27: =IF('Actions Tracker'!A7="","",'Actions Tracker'!AK7) | E27: =IF('Actions Tracker'!A7="","",'Actions Tracker'!AL7)
A28: =IF('Actions Tracker'!A8="","",'Actions Tracker'!A8) | B28: =IF('Actions Tracker'!A8="","",'Actions Tracker'!AJ8) | D28: =IF('Actions Tracker'!A8="","",'Actions Tracker'!AK8) | E28: =IF('Actions Tracker'!A8="","",'Actions Tracker'!AL8)
A29: =IF('Actions Tracker'!A9="","",'Actions Tracker'!A9) | B29: =IF('Actions Tracker'!A9="","",'Actions Tracker'!AJ9) | D29: =IF('Actions Tracker'!A9="","",'Actions Tracker'!AK9) | E29: =IF('Actions Tracker'!A9="","",'Actions Tracker'!AL9)
A30: =IF('Actions Tracker'!A10="","",'Actions Tracker'!A10) | B30: =IF('Actions Tracker'!A10="","",'Actions Tracker'!AJ10) | D30: =IF('Actions Tracker'!A10="","",'Actions Tracker'!AK10) | E30: =IF('Actions Tracker'!A10="","",'Actions Tracker'!AL10)
A31: =IF('Actions Tracker'!A11="","",'Actions Tracker'!A11) | B31: =IF('Actions Tracker'!A11="","",'Actions Tracker'!AJ11) | D31: =IF('Actions Tracker'!A11="","",'Actions Tracker'!AK11) | E31: =IF('Actions Tracker'!A11="","",'Actions Tracker'!AL11)
A34: QUICK NAVIGATION
A35: Goals — Niyyah | D35: Actions — Amal | G35: Belief — Yaqiin
A36: Manifest Board | D36: Daily Journal | G36: Lists / Settings

Sheet Goals (Niyyah)
A1: GOALS — NIYYAH
A3: Define the goals that matter. Mark exactly ONE goal as Primary for the Dashboard.
A5: # | B5: Goal | C5: Category | D5: Why it matters | E5: Affirmation | F5: Start Date | G5: Target Date | H5: Primary? | I5: Status | J5: Linked Actions | K5: Action Rate % | L5: Avg Belief
A6: 1 | J6: =IF(B6="","",COUNTIF('Actions Tracker'!$D$6:$D$25,B6)) | K6: =IF(B6="","",IFERROR(AVERAGEIF('Actions Tracker'!$D$6:$D$25,B6,'Actions Tracker'!$AL$6:$AL$25),"-")) | L6: =IF(B6="","",IFERROR(ROUND(AVERAGEIF('Belief Tracker'!$B$6:$B$65,B6,'Belief Tracker'!$C$6:$C$65),1),"-"))
A7: 2 | J7: =IF(B7="","",COUNTIF('Actions Tracker'!$D$6:$D$25,B7)) | K7: =IF(B7="","",IFERROR(AVERAGEIF('Actions Tracker'!$D$6:$D$25,B7,'Actions Tracker'!$AL$6:$AL$25),"-")) | L7: =IF(B7="","",IFERROR(ROUND(AVERAGEIF('Belief Tracker'!$B$6:$B$65,B7,'Belief Tracker'!$C$6:$C$65),1),"-"))
A8: 3 | J8: =IF(B8="","",COUNTIF('Actions Tracker'!$D$6:$D$25,B8)) | K8: =IF(B8="","",IFERROR(AVERAGEIF('Actions Tracker'!$D$6:$D$25,B8,'Actions Tracker'!$AL$6:$AL$25),"-")) | L8: =IF(B8="","",IFERROR(ROUND(AVERAGEIF('Belief Tracker'!$B$6:$B$65,B8,'Belief Tracker'!$C$6:$C$65),1),"-"))
A9: 4 | J9: =IF(B9="","",COUNTIF('Actions Tracker'!$D$6:$D$25,B9)) | K9: =IF(B9="","",IFERROR(AVERAGEIF('Actions Tracker'!$D$6:$D$25,B9,'Actions Tracker'!$AL$6:$AL$25),"-")) | L9: =IF(B9="","",IFERROR(ROUND(AVERAGEIF('Belief Tracker'!$B$6:$B$65,B9,'Belief Tracker'!$C$6:$C$65),1),"-"))
A10: 5 | J10: =IF(B10="","",COUNTIF('Actions Tracker'!$D$6:$D$25,B10)) | K10: =IF(B10="","",IFERROR(AVERAGEIF('Actions Tracker'!$D$6:$D$25,B10,'Actions Tracker'!$AL$6:$AL$25),"-")) | L10: =IF(B10="","",IFERROR(ROUND(AVERAGEIF('Belief Tracker'!$B$6:$B$65,B10,'Belief Tracker'!$C$6:$C$65),1),"-"))
A11: 6 | J11: =IF(B11="","",COUNTIF('Actions Tracker'!$D$6:$D$25,B11)) | K11: =IF(B11="","",IFERROR(AVERAGEIF('Actions Tracker'!$D$6:$D$25,B11,'Actions Tracker'!$AL$6:$AL$25),"-")) | L11: =IF(B11="","",IFERROR(ROUND(AVERAGEIF('Belief Tracker'!$B$6:$B$65,B11,'Belief Tracker'!$C$6:$C$65),1),"-"))
A12: 7 | J12: =IF(B12="","",COUNTIF('Actions Tracker'!$D$6:$D$25,B12)) | K12: =IF(B12="","",IFERROR(AVERAGEIF('Actions Tracker'!$D$6:$D$25,B12,'Actions Tracker'!$AL$6:$AL$25),"-")) | L12: =IF(B12="","",IFERROR(ROUND(AVERAGEIF('Belief Tracker'!$B$6:$B$65,B12,'Belief Tracker'!$C$6:$C$65),1),"-"))
A13: 8 | J13: =IF(B13="","",COUNTIF('Actions Tracker'!$D$6:$D$25,B13)) | K13: =IF(B13="","",IFERROR(AVERAGEIF('Actions Tracker'!$D$6:$D$25,B13,'Actions Tracker'!$AL$6:$AL$25),"-")) | L13: =IF(B13="","",IFERROR(ROUND(AVERAGEIF('Belief Tracker'!$B$6:$B$65,B13,'Belief Tracker'!$C$6:$C$65),1),"-"))
A14: 9 | J14: =IF(B14="","",COUNTIF('Actions Tracker'!$D$6:$D$25,B14)) | K14: =IF(B14="","",IFERROR(AVERAGEIF('Actions Tracker'!$D$6:$D$25,B14,'Actions Tracker'!$AL$6:$AL$25),"-")) | L14: =IF(B14="","",IFERROR(ROUND(AVERAGEIF('Belief Tracker'!$B$6:$B$65,B14,'Belief Tracker'!$C$6:$C$65),1),"-"))
A15: 10 | J15: =IF(B15="","",COUNTIF('Actions Tracker'!$D$6:$D$25,B15)) | K15: =IF(B15="","",IFERROR(AVERAGEIF('Actions Tracker'!$D$6:$D$25,B15,'Actions Tracker'!$AL$6:$AL$25),"-")) | L15: =IF(B15="","",IFERROR(ROUND(AVERAGEIF('Belief Tracker'!$B$6:$B$65,B15,'Belief Tracker'!$C$6:$C$65),1),"-"))
A16: 11 | J16: =IF(B16="","",COUNTIF('Actions Tracker'!$D$6:$D$25,B16)) | K16: =IF(B16="","",IFERROR(AVERAGEIF('Actions Tracker'!$D$6:$D$25,B16,'Actions Tracker'!$AL$6:$AL$25),"-")) | L16: =IF(B16="","",IFERROR(ROUND(AVERAGEIF('Belief Tracker'!$B$6:$B$65,B16,'Belief Tracker'!$C$6:$C$65),1),"-"))
A17: 12 | J17: =IF(B17="","",COUNTIF('Actions Tracker'!$D$6:$D$25,B17)) | K17: =IF(B17="","",IFERROR(AVERAGEIF('Actions Tracker'!$D$6:$D$25,B17,'Actions Tracker'!$AL$6:$AL$25),"-")) | L17: =IF(B17="","",IFERROR(ROUND(AVERAGEIF('Belief Tracker'!$B$6:$B$65,B17,'Belief Tracker'!$C$6:$C$65),1),"-"))
... A35: 30 | J35: =IF(B35="","",COUNTIF('Actions Tracker'!$D$6:$D$25,B35)) | K35: =IF(B35="","",IFERROR(AVERAGEIF('Actions Tracker'!$D$6:$D$25,B35,'Actions Tracker'!$AL$6:$AL$25),"-")) | L35: =IF(B35="","",IFERROR(ROUND(AVERAGEIF('Belief Tracker'!$B$6:$B$65,B35,'Belief Tracker'!$C$6:$C$65),1),"-"))

Sheet Actions Tracker
A1: ACTIONS TRACKER — AMAL
A3: Track up to 20 repeatable actions. Enter 1 = done, 0 = missed; leave future days blank.
A4: Month starting: | B4: 46266
A5: Action / Habit | B5: Category | C5: Type | D5: Goal | E5: =IF(MONTH($B$4+0)=MONTH($B$4),$B$4+0,"") -> 46266 | F5: =IF(MONTH($B$4+1)=MONTH($B$4),$B$4+1,"") -> 46267 | G5: =IF(MONTH($B$4+2)=MONTH($B$4),$B$4+2,"") -> 46268 | H5: =IF(MONTH($B$4+3)=MONTH($B$4),$B$4+3,"") -> 46269 | I5: =IF(MONTH($B$4+4)=MONTH($B$4),$B$4+4,"") -> 46270 | J5: =IF(MONTH($B$4+5)=MONTH($B$4),$B$4+5,"") -> 46271 | K5: =IF(MONTH($B$4+6)=MONTH($B$4),$B$4+6,"") -> 46272 | L5: =IF(MONTH($B$4+7)=MONTH($B$4),$B$4+7,"") -> 46273 | M5: =IF(MONTH($B$4+8)=MONTH($B$4),$B$4+8,"") -> 46274 | N5: =IF(MONTH($B$4+9)=MONTH($B$4),$B$4+9,"") -> 46275 | O5: =IF(MONTH($B$4+10)=MONTH($B$4),$B$4+10,"") -> 46276 | P5: =IF(MONTH($B$4+11)=MONTH($B$4),$B$4+11,"") -> 46277 | Q5: =IF(MONTH($B$4+12)=MONTH($B$4),$B$4+12,"") -> 46278 | R5: =IF(MONTH($B$4+13)=MONTH($B$4),$B$4+13,"") -> 46279 | S5: =IF(MONTH($B$4+14)=MONTH($B$4),$B$4+14,"") -> 46280 | T5: =IF(MONTH($B$4+15)=MONTH($B$4),$B$4+15,"") -> 46281 | U5: =IF(MONTH($B$4+16)=MONTH($B$4),$B$4+16,"") -> 46282 | V5: =IF(MONTH($B$4+17)=MONTH($B$4),$B$4+17,"") -> 46283 | W5: =IF(MONTH($B$4+18)=MONTH($B$4),$B$4+18,"") -> 46284 | X5: =IF(MONTH($B$4+19)=MONTH($B$4),$B$4+19,"") -> 46285 | Y5: =IF(MONTH($B$4+20)=MONTH($B$4),$B$4+20,"") -> 46286 | Z5: =IF(MONTH($B$4+21)=MONTH($B$4),$B$4+21,"") -> 46287 | AA5: =IF(MONTH($B$4+22)=MONTH($B$4),$B$4+22,"") -> 46288 | AB5: =IF(MONTH($B$4+23)=MONTH($B$4),$B$4+23,"") -> 46289 | AC5: =IF(MONTH($B$4+24)=MONTH($B$4),$B$4+24,"") -> 46290 | AD5: =IF(MONTH($B$4+25)=MONTH($B$4),$B$4+25,"") -> 46291 | AE5: =IF(MONTH($B$4+26)=MONTH($B$4),$B$4+26,"") -> 46292 | AF5: =IF(MONTH($B$4+27)=MONTH($B$4),$B$4+27,"") -> 46293 | AG5: =IF(MONTH($B$4+28)=MONTH($B$4),$B$4+28,"") -> 46294 | AH5: =IF(MONTH($B$4+29)=MONTH($B$4),$B$4+29,"") -> 46295 | AI5: =IF(MONTH($B$4+30)=MONTH($B$4),$B$4+30,"") | AJ5: Done | AK5: Missed | AL5: Rate %
AJ6: =COUNTIF(E6:AI6,1) -> 0 | AK6: =COUNTIF(E6:AI6,0) -> 0 | AL6: =IF(COUNT(E6:AI6)=0,"-",AJ6/COUNT(E6:AI6)) -> -
AJ7: =COUNTIF(E7:AI7,1) -> 0 | AK7: =COUNTIF(E7:AI7,0) -> 0 | AL7: =IF(COUNT(E7:AI7)=0,"-",AJ7/COUNT(E7:AI7)) -> -
AJ8: =COUNTIF(E8:AI8,1) -> 0 | AK8: =COUNTIF(E8:AI8,0) -> 0 | AL8: =IF(COUNT(E8:AI8)=0,"-",AJ8/COUNT(E8:AI8)) -> -
AJ9: =COUNTIF(E9:AI9,1) -> 0 | AK9: =COUNTIF(E9:AI9,0) -> 0 | AL9: =IF(COUNT(E9:AI9)=0,"-",AJ9/COUNT(E9:AI9)) -> -
AJ10: =COUNTIF(E10:AI10,1) -> 0 | AK10: =COUNTIF(E10:AI10,0) -> 0 | AL10: =IF(COUNT(E10:AI10)=0,"-",AJ10/COUNT(E10:AI10)) -> -
AJ11: =COUNTIF(E11:AI11,1) -> 0 | AK11: =COUNTIF(E11:AI11,0) -> 0 | AL11: =IF(COUNT(E11:AI11)=0,"-",AJ11/COUNT(E11:AI11)) -> -
AJ12: =COUNTIF(E12:AI12,1) -> 0 | AK12: =COUNTIF(E12:AI12,0) -> 0 | AL12: =IF(COUNT(E12:AI12)=0,"-",AJ12/COUNT(E12:AI12)) -> -
AJ13: =COUNTIF(E13:AI13,1) -> 0 | AK13: =COUNTIF(E13:AI13,0) -> 0 | AL13: =IF(COUNT(E13:AI13)=0,"-",AJ13/COUNT(E13:AI13)) -> -
AJ14: =COUNTIF(E14:AI14,1) -> 0 | AK14: =COUNTIF(E14:AI14,0) -> 0 | AL14: =IF(COUNT(E14:AI14)=0,"-",AJ14/COUNT(E14:AI14)) -> -
AJ15: =COUNTIF(E15:AI15,1) -> 0 | AK15: =COUNTIF(E15:AI15,0) -> 0 | AL15: =IF(COUNT(E15:AI15)=0,"-",AJ15/COUNT(E15:AI15)) -> -
AJ16: =COUNTIF(E16:AI16,1) -> 0 | AK16: =COUNTIF(E16:AI16,0) -> 0 | AL16: =IF(COUNT(E16:AI16)=0,"-",AJ16/COUNT(E16:AI16)) -> -
AJ17: =COUNTIF(E17:AI17,1) -> 0 | AK17: =COUNTIF(E17:AI17,0) -> 0 | AL17: =IF(COUNT(E17:AI17)=0,"-",AJ17/COUNT(E17:AI17)) -> -
... AJ25: =COUNTIF(E25:AI25,1) -> 0 | AK25: =COUNTIF(E25:AI25,0) -> 0 | AL25: =IF(COUNT(E25:AI25)=0,"-",AJ25/COUNT(E25:AI25)) -> -
A27: TOTAL | AJ27: =SUM(AJ6:AJ25) -> 0 | AK27: =SUM(AK6:AK25) -> 0 | AL27: =IF(AJ27+AK27=0,"-",AJ27/(AJ27+AK27)) -> -
A28: DAY COMPLETION | E28: =IF(COUNT(E6:E25)=0,"-",COUNTIF(E6:E25,1)/COUNT(E6:E25)) -> - | F28: =IF(COUNT(F6:F25)=0,"-",COUNTIF(F6:F25,1)/COUNT(F6:F25)) -> - | G28: =IF(COUNT(G6:G25)=0,"-",COUNTIF(G6:G25,1)/COUNT(G6:G25)) -> - | H28: =IF(COUNT(H6:H25)=0,"-",COUNTIF(H6:H25,1)/COUNT(H6:H25)) -> - | I28: =IF(COUNT(I6:I25)=0,"-",COUNTIF(I6:I25,1)/COUNT(I6:I25)) -> - | J28: =IF(COUNT(J6:J25)=0,"-",COUNTIF(J6:J25,1)/COUNT(J6:J25)) -> - | K28: =IF(COUNT(K6:K25)=0,"-",COUNTIF(K6:K25,1)/COUNT(K6:K25)) -> - | L28: =IF(COUNT(L6:L25)=0,"-",COUNTIF(L6:L25,1)/COUNT(L6:L25)) -> - | ... AI28: =IF(COUNT(AI6:AI25)=0,"-",COUNTIF(AI6:AI25,1)/COUNT(AI6:AI25)) -> -
A29: STREAK | E29: =IF(E28="-","",IF(E28=1,1,0)) | F29: =IF(F28="-","",IF(F28=1,E29+1,0)) | G29: =IF(G28="-","",IF(G28=1,F29+1,0)) | H29: =IF(H28="-","",IF(H28=1,G29+1,0)) | I29: =IF(I28="-","",IF(I28=1,H29+1,0)) | J29: =IF(J28="-","",IF(J28=1,I29+1,0)) | K29: =IF(K28="-","",IF(K28=1,J29+1,0)) | L29: =IF(L28="-","",IF(L28=1,K29+1,0)) | M29: =IF(M28="-","",IF(M28=1,L29+1,0)) | ... AI29: =IF(AI28="-","",IF(AI28=1,AH29+1,0))

Sheet Belief Tracker
A1: BELIEF TRACKER — YAQIIN
A3: Rate your belief from 1–10 and capture one honest shift each day.
A5: Date | B5: Goal | C5: Belief (1-10) | D5: What shifted today | E5: Actions done that day
A6: ='Actions Tracker'!$B$4+0 -> 46266 | E6: =IFERROR(SUM(INDEX('Actions Tracker'!$E$6:$AI$25,0,MATCH(A6,'Actions Tracker'!$E$5:$AI$5,0))),"-") -> 0
A7: ='Actions Tracker'!$B$4+1 -> 46267 | E7: =IFERROR(SUM(INDEX('Actions Tracker'!$E$6:$AI$25,0,MATCH(A7,'Actions Tracker'!$E$5:$AI$5,0))),"-") -> 0
A8: ='Actions Tracker'!$B$4+2 -> 46268 | E8: =IFERROR(SUM(INDEX('Actions Tracker'!$E$6:$AI$25,0,MATCH(A8,'Actions Tracker'!$E$5:$AI$5,0))),"-") -> 0
A9: ='Actions Tracker'!$B$4+3 -> 46269 | E9: =IFERROR(SUM(INDEX('Actions Tracker'!$E$6:$AI$25,0,MATCH(A9,'Actions Tracker'!$E$5:$AI$5,0))),"-") -> 0
A10: ='Actions Tracker'!$B$4+4 -> 46270 | E10: =IFERROR(SUM(INDEX('Actions Tracker'!$E$6:$AI$25,0,MATCH(A10,'Actions Tracker'!$E$5:$AI$5,0))),"-") -> 0
A11: ='Actions Tracker'!$B$4+5 -> 46271 | E11: =IFERROR(SUM(INDEX('Actions Tracker'!$E$6:$AI$25,0,MATCH(A11,'Actions Tracker'!$E$5:$AI$5,0))),"-") -> 0
A12: ='Actions Tracker'!$B$4+6 -> 46272 | E12: =IFERROR(SUM(INDEX('Actions Tracker'!$E$6:$AI$25,0,MATCH(A12,'Actions Tracker'!$E$5:$AI$5,0))),"-") -> 0
A13: ='Actions Tracker'!$B$4+7 -> 46273 | E13: =IFERROR(SUM(INDEX('Actions Tracker'!$E$6:$AI$25,0,MATCH(A13,'Actions Tracker'!$E$5:$AI$5,0))),"-") -> 0
A14: ='Actions Tracker'!$B$4+8 -> 46274 | E14: =IFERROR(SUM(INDEX('Actions Tracker'!$E$6:$AI$25,0,MATCH(A14,'Actions Tracker'!$E$5:$AI$5,0))),"-") -> 0
A15: ='Actions Tracker'!$B$4+9 -> 46275 | E15: =IFERROR(SUM(INDEX('Actions Tracker'!$E$6:$AI$25,0,MATCH(A15,'Actions Tracker'!$E$5:$AI$5,0))),"-") -> 0
A16: ='Actions Tracker'!$B$4+10 -> 46276 | E16: =IFERROR(SUM(INDEX('Actions Tracker'!$E$6:$AI$25,0,MATCH(A16,'Actions Tracker'!$E$5:$AI$5,0))),"-") -> 0
A17: ='Actions Tracker'!$B$4+11 -> 46277 | E17: =IFERROR(SUM(INDEX('Actions Tracker'!$E$6:$AI$25,0,MATCH(A17,'Actions Tracker'!$E$5:$AI$5,0))),"-") -> 0
A18: ='Actions Tracker'!$B$4+12 -> 46278 | E18: =IFERROR(SUM(INDEX('Actions Tracker'!$E$6:$AI$25,0,MATCH(A18,'Actions Tracker'!$E$5:$AI$5,0))),"-") -> 0
A19: ='Actions Tracker'!$B$4+13 -> 46279 | E19: =IFERROR(SUM(INDEX('Actions Tracker'!$E$6:$AI$25,0,MATCH(A19,'Actions Tracker'!$E$5:$AI$5,0))),"-") -> 0
A20: ='Actions Tracker'!$B$4+14 -> 46280 | E20: =IFERROR(SUM(INDEX('Actions Tracker'!$E$6:$AI$25,0,MATCH(A20,'Actions Tracker'!$E$5:$AI$5,0))),"-") -> 0
A21: ='Actions Tracker'!$B$4+15 -> 46281 | E21: =IFERROR(SUM(INDEX('Actions Tracker'!$E$6:$AI$25,0,MATCH(A21,'Actions Tracker'!$E$5:$AI$5,0))),"-") -> 0
A22: ='Actions Tracker'!$B$4+16 -> 46282 | E22: =IFERROR(SUM(INDEX('Actions Tracker'!$E$6:$AI$25,0,MATCH(A22,'Actions Tracker'!$E$5:$AI$5,0))),"-") -> 0
A23: ='Actions Tracker'!$B$4+17 -> 46283 | E23: =IFERROR(SUM(INDEX('Actions Tracker'!$E$6:$AI$25,0,MATCH(A23,'Actions Tracker'!$E$5:$AI$5,0))),"-") -> 0
A24: ='Actions Tracker'!$B$4+18 -> 46284 | E24: =IFERROR(SUM(INDEX('Actions Tracker'!$E$6:$AI$25,0,MATCH(A24,'Actions Tracker'!$E$5:$AI$5,0))),"-") -> 0
A25: ='Actions Tracker'!$B$4+19 -> 46285 | E25: =IFERROR(SUM(INDEX('Actions Tracker'!$E$6:$AI$25,0,MATCH(A25,'Actions Tracker'!$E$5:$AI$5,0))),"-") -> 0
A26: ='Actions Tracker'!$B$4+20 -> 46286 | E26: =IFERROR(SUM(INDEX('Actions Tracker'!$E$6:$AI$25,0,MATCH(A26,'Actions Tracker'!$E$5:$AI$5,0))),"-") -> 0
A27: ='Actions Tracker'!$B$4+21 -> 46287 | E27: =IFERROR(SUM(INDEX('Actions Tracker'!$E$6:$AI$25,0,MATCH(A27,'Actions Tracker'!$E$5:$AI$5,0))),"-") -> 0
A28: ='Actions Tracker'!$B$4+22 -> 46288 | E28: =IFERROR(SUM(INDEX('Actions Tracker'!$E$6:$AI$25,0,MATCH(A28,'Actions Tracker'!$E$5:$AI$5,0))),"-") -> 0
A29: ='Actions Tracker'!$B$4+23 -> 46289 | E29: =IFERROR(SUM(INDEX('Actions Tracker'!$E$6:$AI$25,0,MATCH(A29,'Actions Tracker'!$E$5:$AI$5,0))),"-") -> 0
A30: ='Actions Tracker'!$B$4+24 -> 46290 | E30: =IFERROR(SUM(INDEX('Actions Tracker'!$E$6:$AI$25,0,MATCH(A30,'Actions Tracker'!$E$5:$AI$5,0))),"-") -> 0
A31: ='Actions Tracker'!$B$4+25 -> 46291 | E31: =IFERROR(SUM(INDEX('Actions Tracker'!$E$6:$AI$25,0,MATCH(A31,'Actions Tracker'!$E$5:$AI$5,0))),"-") -> 0
A32: ='Actions Tracker'!$B$4+26 -> 46292 | E32: =IFERROR(SUM(INDEX('Actions Tracker'!$E$6:$AI$25,0,MATCH(A32,'Actions Tracker'!$E$5:$AI$5,0))),"-") -> 0
A33: ='Actions Tracker'!$B$4+27 -> 46293 | E33: =IFERROR(SUM(INDEX('Actions Tracker'!$E$6:$AI$25,0,MATCH(A33,'Actions Tracker'!$E$5:$AI$5,0))),"-") -> 0
A34: ='Actions Tracker'!$B$4+28 -> 46294 | E34: =IFERROR(SUM(INDEX('Actions Tracker'!$E$6:$AI$25,0,MATCH(A34,'Actions Tracker'!$E$5:$AI$5,0))),"-") -> 0
A35: ='Actions Tracker'!$B$4+29 -> 46295 | E35: =IFERROR(SUM(INDEX('Actions Tracker'!$E$6:$AI$25,0,MATCH(A35,'Actions Tracker'!$E$5:$AI$5,0))),"-") -> 0
A36: ='Actions Tracker'!$B$4+30 -> 46296 | E36: =IFERROR(SUM(INDEX('Actions Tracker'!$E$6:$AI$25,0,MATCH(A36,'Actions Tracker'!$E$5:$AI$5,0))),"-") -> -
A37: ='Actions Tracker'!$B$4+31 -> 46297 | E37: =IFERROR(SUM(INDEX('Actions Tracker'!$E$6:$AI$25,0,MATCH(A37,'Actions Tracker'!$E$5:$AI$5,0))),"-") -> -
A38: ='Actions Tracker'!$B$4+32 -> 46298 | E38: =IFERROR(SUM(INDEX('Actions Tracker'!$E$6:$AI$25,0,MATCH(A38,'Actions Tracker'!$E$5:$AI$5,0))),"-") -> -
A39: ='Actions Tracker'!$B$4+33 -> 46299 | E39: =IFERROR(SUM(INDEX('Actions Tracker'!$E$6:$AI$25,0,MATCH(A39,'Actions Tracker'!$E$5:$AI$5,0))),"-") -> -
A40: ='Actions Tracker'!$B$4+34 -> 46300 | E40: =IFERROR(SUM(INDEX('Actions Tracker'!$E$6:$AI$25,0,MATCH(A40,'Actions Tracker'!$E$5:$AI$5,0))),"-") -> -
A41: ='Actions Tracker'!$B$4+35 -> 46301 | E41: =IFERROR(SUM(INDEX('Actions Tracker'!$E$6:$AI$25,0,MATCH(A41,'Actions Tracker'!$E$5:$AI$5,0))),"-") -> -
A42: ='Actions Tracker'!$B$4+36 -> 46302 | E42: =IFERROR(SUM(INDEX('Actions Tracker'!$E$6:$AI$25,0,MATCH(A42,'Actions Tracker'!$E$5:$AI$5,0))),"-") -> -
...

Sheet Manifest Board
A1: MANIFEST BOARD
A3: A simple three-part reflection practice: Ask · Gratitude · Receive.
A5: Date | B5: Type | C5: Entry | D5: Answered?

Sheet Daily Journal
A1: DAILY JOURNAL
A3: One honest paragraph beats ten perfect ones.
A5: Date | B5: Reflection | C5: Win of the day | D5: Lesson | E5: Tomorrow's one focus
A6: ='Actions Tracker'!$B$4+0 -> 46266
A7: ='Actions Tracker'!$B$4+1 -> 46267
A8: ='Actions Tracker'!$B$4+2 -> 46268
A9: ='Actions Tracker'!$B$4+3 -> 46269
A10: ='Actions Tracker'!$B$4+4 -> 46270
A11: ='Actions Tracker'!$B$4+5 -> 46271
A12: ='Actions Tracker'!$B$4+6 -> 46272
A13: ='Actions Tracker'!$B$4+7 -> 46273
A14: ='Actions Tracker'!$B$4+8 -> 46274
A15: ='Actions Tracker'!$B$4+9 -> 46275
A16: ='Actions Tracker'!$B$4+10 -> 46276
A17: ='Actions Tracker'!$B$4+11 -> 46277
A18: ='Actions Tracker'!$B$4+12 -> 46278
A19: ='Actions Tracker'!$B$4+13 -> 46279
A20: ='Actions Tracker'!$B$4+14 -> 46280
A21: ='Actions Tracker'!$B$4+15 -> 46281
A22: ='Actions Tracker'!$B$4+16 -> 46282
A23: ='Actions Tracker'!$B$4+17 -> 46283
A24: ='Actions Tracker'!$B$4+18 -> 46284
A25: ='Actions Tracker'!$B$4+19 -> 46285
A26: ='Actions Tracker'!$B$4+20 -> 46286
A27: ='Actions Tracker'!$B$4+21 -> 46287
A28: ='Actions Tracker'!$B$4+22 -> 46288
A29: ='Actions Tracker'!$B$4+23 -> 46289
A30: ='Actions Tracker'!$B$4+24 -> 46290
A31: ='Actions Tracker'!$B$4+25 -> 46291
A32: ='Actions Tracker'!$B$4+26 -> 46292
A33: ='Actions Tracker'!$B$4+27 -> 46293
A34: ='Actions Tracker'!$B$4+28 -> 46294
A35: ='Actions Tracker'!$B$4+29 -> 46295
A36: ='Actions Tracker'!$B$4+30 -> 46296
A37: ='Actions Tracker'!$B$4+31 -> 46297
A38: ='Actions Tracker'!$B$4+32 -> 46298
A39: ='Actions Tracker'!$B$4+33 -> 46299
A40: ='Actions Tracker'!$B$4+34 -> 46300
A41: ='Actions Tracker'!$B$4+35 -> 46301
A42: ='Actions Tracker'!$B$4+36 -> 46302
...

Sheet Lists
A1: LISTS
A3: Edit these values to customize dropdown menus throughout the planner.
A5: Category | B5: Status | C5: Action Type | D5: Manifest Type
A6: Spirituality | B6: Not Started | C6: Daily | D6: Ask
A7: Health | B7: In Progress | C7: Weekly | D7: Gratitude
A8: Wealth | B8: Achieved | C8: Monthly | D8: Receive
A9: Knowledge | B9: Paused
A10: Relationships
